<sdf version='1.6'>
  <world name='default'>
    <light name='sun' type='directional'>
      <cast_shadows>1</cast_shadows>
      <pose frame=''>0 0 10 0 -0 0</pose>
      <diffuse>0.8 0.8 0.8 1</diffuse>
      <specular>0.2 0.2 0.2 1</specular>
      <attenuation>
        <range>1000</range>
        <constant>0.9</constant>
        <linear>0.01</linear>
        <quadratic>0.001</quadratic>
      </attenuation>
      <direction>-0.5 0.1 -0.9</direction>
    </light>
    <model name='ground_plane'>
      <static>1</static>
      <link name='link'>
        <collision name='collision'>
          <geometry>
            <plane>
              <normal>0 0 1</normal>
              <size>100 100</size>
            </plane>
          </geometry>
          <surface>
            <friction>
              <ode>
                <mu>100</mu>
                <mu2>50</mu2>
              </ode>
              <torsional>
                <ode/>
              </torsional>
            </friction>
            <contact>
              <ode/>
            </contact>
            <bounce/>
          </surface>
          <max_contacts>10</max_contacts>
        </collision>
        <visual name='visual'>
          <cast_shadows>0</cast_shadows>
          <geometry>
            <plane>
              <normal>0 0 1</normal>
              <size>100 100</size>
            </plane>
          </geometry>
          <material>
            <script>
              <uri>file://media/materials/scripts/gazebo.material</uri>
              <name>Gazebo/Grey</name>
            </script>
          </material>
        </visual>
        <self_collide>0</self_collide>
        <kinematic>0</kinematic>
      </link>
    </model>
    <gravity>0 0 -9.8</gravity>
    <magnetic_field>6e-06 2.3e-05 -4.2e-05</magnetic_field>
    <atmosphere type='adiabatic'/>
    <physics name='default_physics' default='0' type='ode'>
      <max_step_size>0.001</max_step_size>
      <real_time_factor>1</real_time_factor>
      <real_time_update_rate>1000</real_time_update_rate>
    </physics>
    <scene>
      <ambient>0.4 0.4 0.4 1</ambient>
      <background>0.7 0.7 0.7 1</background>
      <shadows>1</shadows>
    </scene>
    <spherical_coordinates>
      <surface_model>EARTH_WGS84</surface_model>
      <latitude_deg>0</latitude_deg>
      <longitude_deg>0</longitude_deg>
      <elevation>0</elevation>
      <heading_deg>0</heading_deg>
    </spherical_coordinates>
    <model name='robot'>
      <link name='link_0'>
        <pose frame=''>0 0 -0.23 0 -0 0</pose>
        <inertial>
          <mass>1</mass>
          <inertia>
            <ixx>0.166667</ixx>
            <ixy>0</ixy>
            <ixz>0</ixz>
            <iyy>0.166667</iyy>
            <iyz>0</iyz>
            <izz>0.166667</izz>
          </inertia>
          <pose frame=''>0 0 0 0 -0 0</pose>
        </inertial>
        <gravity>1</gravity>
        <self_collide>0</self_collide>
        <kinematic>0</kinematic>
        <visual name='visual'>
          <pose frame=''>0 0 0 0 -0 0</pose>
          <geometry>
            <box>
              <size>0.5 0.7 0.1</size>
            </box>
          </geometry>
          <material>
            <lighting>1</lighting>
            <script>
              <uri>file://media/materials/scripts/gazebo.material</uri>
              <name>Gazebo/Grey</name>
            </script>
            <shader type='pixel'>
              <normal_map>__default__</normal_map>
            </shader>
            <ambient>0.3 0.3 0.3 1</ambient>
            <diffuse>0.7 0.7 0.7 1</diffuse>
            <specular>0.01 0.01 0.01 1</specular>
            <emissive>0 0 0 1</emissive>
          </material>
          <transparency>0</transparency>
          <cast_shadows>1</cast_shadows>
        </visual>
        <collision name='collision'>
          <laser_retro>0</laser_retro>
          <max_contacts>10</max_contacts>
          <pose frame=''>0 0 0 0 -0 0</pose>
          <geometry>
            <box>
              <size>0.5 0.7 0.1</size>
            </box>
          </geometry>
          <surface>
            <friction>
              <ode>
                <mu>1</mu>
                <mu2>1</mu2>
                <fdir1>0 0 0</fdir1>
                <slip1>0</slip1>
                <slip2>0</slip2>
              </ode>
              <torsional>
                <coefficient>1</coefficient>
                <patch_radius>0</patch_radius>
                <surface_radius>0</surface_radius>
                <use_patch_radius>1</use_patch_radius>
                <ode>
                  <slip>0</slip>
                </ode>
              </torsional>
            </friction>
            <bounce>
              <restitution_coefficient>0</restitution_coefficient>
              <threshold>1e+06</threshold>
            </bounce>
            <contact>
              <collide_without_contact>0</collide_without_contact>
              <collide_without_contact_bitmask>1</collide_without_contact_bitmask>
              <collide_bitmask>1</collide_bitmask>
              <ode>
                <soft_cfm>0</soft_cfm>
                <soft_erp>0.2</soft_erp>
                <kp>1e+13</kp>
                <kd>1</kd>
                <max_vel>0.01</max_vel>
                <min_depth>0</min_depth>
              </ode>
              <bullet>
                <split_impulse>1</split_impulse>
                <split_impulse_penetration_threshold>-0.01</split_impulse_penetration_threshold>
                <soft_cfm>0</soft_cfm>
                <soft_erp>0.2</soft_erp>
                <kp>1e+13</kp>
                <kd>1</kd>
              </bullet>
            </contact>
          </surface>
        </collision>
      </link>
      <link name='link_1'>
        <pose frame=''>0 -0.400019 -0.23 1.5707 -0 0</pose>
        <inertial>
          <mass>1</mass>
          <inertia>
            <ixx>0.145833</ixx>
            <ixy>0</ixy>
            <ixz>0</ixz>
            <iyy>0.145833</iyy>
            <iyz>0</iyz>
            <izz>0.125</izz>
          </inertia>
          <pose frame=''>0 0 0 0 -0 0</pose>
        </inertial>
        <gravity>1</gravity>
        <self_collide>0</self_collide>
        <kinematic>0</kinematic>
        <visual name='visual'>
          <pose frame=''>0 0 0 0 -0 0</pose>
          <geometry>
            <cylinder>
              <radius>0.2</radius>
              <length>0.1</length>
            </cylinder>
          </geometry>
          <material>
            <lighting>1</lighting>
            <script>
              <uri>file://media/materials/scripts/gazebo.material</uri>
              <name>Gazebo/Grey</name>
            </script>
            <shader type='pixel'>
              <normal_map>__default__</normal_map>
            </shader>
            <ambient>0.3 0.3 0.3 1</ambient>
            <diffuse>0.7 0.7 0.7 1</diffuse>
            <specular>0.01 0.01 0.01 1</specular>
            <emissive>0 0 0 1</emissive>
          </material>
          <transparency>0</transparency>
          <cast_shadows>1</cast_shadows>
        </visual>
        <collision name='collision'>
          <laser_retro>0</laser_retro>
          <max_contacts>10</max_contacts>
          <pose frame=''>0 0 0 0 -0 0</pose>
          <geometry>
            <cylinder>
              <radius>0.2</radius>
              <length>0.1</length>
            </cylinder>
          </geometry>
          <surface>
            <friction>
              <ode>
                <mu>1</mu>
                <mu2>1</mu2>
                <fdir1>0 0 0</fdir1>
                <slip1>0</slip1>
                <slip2>0</slip2>
              </ode>
              <torsional>
                <coefficient>1</coefficient>
                <patch_radius>0</patch_radius>
                <surface_radius>0</surface_radius>
                <use_patch_radius>1</use_patch_radius>
                <ode>
                  <slip>0</slip>
                </ode>
              </torsional>
            </friction>
            <bounce>
              <restitution_coefficient>0</restitution_coefficient>
              <threshold>1e+06</threshold>
            </bounce>
            <contact>
              <collide_without_contact>0</collide_without_contact>
              <collide_without_contact_bitmask>1</collide_without_contact_bitmask>
              <collide_bitmask>1</collide_bitmask>
              <ode>
                <soft_cfm>0</soft_cfm>
                <soft_erp>0.2</soft_erp>
                <kp>1e+13</kp>
                <kd>1</kd>
                <max_vel>0.01</max_vel>
                <min_depth>0</min_depth>
              </ode>
              <bullet>
                <split_impulse>1</split_impulse>
                <split_impulse_penetration_threshold>-0.01</split_impulse_penetration_threshold>
                <soft_cfm>0</soft_cfm>
                <soft_erp>0.2</soft_erp>
                <kp>1e+13</kp>
                <kd>1</kd>
              </bullet>
            </contact>
          </surface>
        </collision>
      </link>
      <link name='link_1_clone'>
        <pose frame=''>0 0.400019 -0.23 1.5707 -0 0</pose>
        <inertial>
          <mass>1</mass>
          <inertia>
            <ixx>0.145833</ixx>
            <ixy>0</ixy>
            <ixz>0</ixz>
            <iyy>0.145833</iyy>
            <iyz>0</iyz>
            <izz>0.125</izz>
          </inertia>
          <pose frame=''>0 0 0 0 -0 0</pose>
        </inertial>
        <self_collide>0</self_collide>
        <kinematic>0</kinematic>
        <visual name='visual'>
          <pose frame=''>0 0 0 0 -0 0</pose>
          <geometry>
            <cylinder>
              <radius>0.2</radius>
              <length>0.1</length>
            </cylinder>
          </geometry>
          <material>
            <lighting>1</lighting>
            <script>
              <uri>file://media/materials/scripts/gazebo.material</uri>
              <name>Gazebo/Grey</name>
            </script>
            <shader type='pixel'>
              <normal_map>__default__</normal_map>
            </shader>
            <ambient>0.3 0.3 0.3 1</ambient>
            <diffuse>0.7 0.7 0.7 1</diffuse>
            <specular>0.01 0.01 0.01 1</specular>
            <emissive>0 0 0 1</emissive>
          </material>
          <transparency>0</transparency>
          <cast_shadows>1</cast_shadows>
        </visual>
        <collision name='collision'>
          <laser_retro>0</laser_retro>
          <max_contacts>10</max_contacts>
          <pose frame=''>0 0 0 0 -0 0</pose>
          <geometry>
            <cylinder>
              <radius>0.2</radius>
              <length>0.1</length>
            </cylinder>
          </geometry>
          <surface>
            <friction>
              <ode>
                <mu>1</mu>
                <mu2>1</mu2>
                <fdir1>0 0 0</fdir1>
                <slip1>0</slip1>
                <slip2>0</slip2>
              </ode>
              <torsional>
                <coefficient>1</coefficient>
                <patch_radius>0</patch_radius>
                <surface_radius>0</surface_radius>
                <use_patch_radius>1</use_patch_radius>
                <ode>
                  <slip>0</slip>
                </ode>
              </torsional>
            </friction>
            <bounce>
              <restitution_coefficient>0</restitution_coefficient>
              <threshold>1e+06</threshold>
            </bounce>
            <contact>
              <collide_without_contact>0</collide_without_contact>
              <collide_without_contact_bitmask>1</collide_without_contact_bitmask>
              <collide_bitmask>1</collide_bitmask>
              <ode>
                <soft_cfm>0</soft_cfm>
                <soft_erp>0.2</soft_erp>
                <kp>1e+13</kp>
                <kd>1</kd>
                <max_vel>0.01</max_vel>
                <min_depth>0</min_depth>
              </ode>
              <bullet>
                <split_impulse>1</split_impulse>
                <split_impulse_penetration_threshold>-0.01</split_impulse_penetration_threshold>
                <soft_cfm>0</soft_cfm>
                <soft_erp>0.2</soft_erp>
                <kp>1e+13</kp>
                <kd>1</kd>
              </bullet>
            </contact>
          </surface>
        </collision>
      </link>
      <link name='link_4'>
        <pose frame=''>0 0 0.07 0 -0 0</pose>
        <inertial>
          <mass>1</mass>
          <inertia>
            <ixx>0.166667</ixx>
            <ixy>0</ixy>
            <ixz>0</ixz>
            <iyy>0.166667</iyy>
            <iyz>0</iyz>
            <izz>0.166667</izz>
          </inertia>
          <pose frame=''>0 0 0 0 -0 0</pose>
        </inertial>
        <gravity>1</gravity>
        <self_collide>0</self_collide>
        <kinematic>0</kinematic>
        <visual name='visual'>
          <pose frame=''>0 0 0 0 -0 0</pose>
          <geometry>
            <box>
              <size>0.4 0.5 0.7</size>
            </box>
          </geometry>
          <material>
            <lighting>1</lighting>
            <script>
              <uri>file://media/materials/scripts/gazebo.material</uri>
              <name>Gazebo/Grey</name>
            </script>
            <shader type='pixel'>
              <normal_map>__default__</normal_map>
            </shader>
            <ambient>0.3 0.3 0.3 1</ambient>
            <diffuse>0.7 0.7 0.7 1</diffuse>
            <specular>0.01 0.01 0.01 1</specular>
            <emissive>0 0 0 1</emissive>
          </material>
          <transparency>0</transparency>
          <cast_shadows>1</cast_shadows>
        </visual>
        <collision name='collision'>
          <laser_retro>0</laser_retro>
          <max_contacts>10</max_contacts>
          <pose frame=''>0 0 0 0 -0 0</pose>
          <geometry>
            <box>
              <size>0.4 0.5 0.7</size>
            </box>
          </geometry>
          <surface>
            <friction>
              <ode>
                <mu>1</mu>
                <mu2>1</mu2>
                <fdir1>0 0 0</fdir1>
                <slip1>0</slip1>
                <slip2>0</slip2>
              </ode>
              <torsional>
                <coefficient>1</coefficient>
                <patch_radius>0</patch_radius>
                <surface_radius>0</surface_radius>
                <use_patch_radius>1</use_patch_radius>
                <ode>
                  <slip>0</slip>
                </ode>
              </torsional>
            </friction>
            <bounce>
              <restitution_coefficient>0</restitution_coefficient>
              <threshold>1e+06</threshold>
            </bounce>
            <contact>
              <collide_without_contact>0</collide_without_contact>
              <collide_without_contact_bitmask>1</collide_without_contact_bitmask>
              <collide_bitmask>1</collide_bitmask>
              <ode>
                <soft_cfm>0</soft_cfm>
                <soft_erp>0.2</soft_erp>
                <kp>1e+13</kp>
                <kd>1</kd>
                <max_vel>0.01</max_vel>
                <min_depth>0</min_depth>
              </ode>
              <bullet>
                <split_impulse>1</split_impulse>
                <split_impulse_penetration_threshold>-0.01</split_impulse_penetration_threshold>
                <soft_cfm>0</soft_cfm>
                <soft_erp>0.2</soft_erp>
                <kp>1e+13</kp>
                <kd>1</kd>
              </bullet>
            </contact>
          </surface>
        </collision>
      </link>
      <link name='link_5'>
        <pose frame=''>0 0 0.62 0 -0 0</pose>
        <inertial>
          <mass>1</mass>
          <inertia>
            <ixx>0.1</ixx>
            <ixy>0</ixy>
            <ixz>0</ixz>
            <iyy>0.1</iyy>
            <iyz>0</iyz>
            <izz>0.1</izz>
          </inertia>
          <pose frame=''>0 0 0 0 -0 0</pose>
        </inertial>
        <gravity>1</gravity>
        <self_collide>0</self_collide>
        <kinematic>0</kinematic>
        <visual name='visual'>
          <pose frame=''>0 0 0 0 -0 0</pose>
          <geometry>
            <sphere>
              <radius>0.2</radius>
            </sphere>
          </geometry>
          <material>
            <lighting>1</lighting>
            <script>
              <uri>file://media/materials/scripts/gazebo.material</uri>
              <name>Gazebo/Grey</name>
            </script>
            <shader type='pixel'>
              <normal_map>__default__</normal_map>
            </shader>
            <ambient>0.3 0.3 0.3 1</ambient>
            <diffuse>0.7 0.7 0.7 1</diffuse>
            <specular>0.01 0.01 0.01 1</specular>
            <emissive>0 0 0 1</emissive>
          </material>
          <transparency>0</transparency>
          <cast_shadows>1</cast_shadows>
        </visual>
        <collision name='collision'>
          <laser_retro>0</laser_retro>
          <max_contacts>10</max_contacts>
          <pose frame=''>0 0 0 0 -0 0</pose>
          <geometry>
            <sphere>
              <radius>0.2</radius>
            </sphere>
          </geometry>
          <surface>
            <friction>
              <ode>
                <mu>1</mu>
                <mu2>1</mu2>
                <fdir1>0 0 0</fdir1>
                <slip1>0</slip1>
                <slip2>0</slip2>
              </ode>
              <torsional>
                <coefficient>1</coefficient>
                <patch_radius>0</patch_radius>
                <surface_radius>0</surface_radius>
                <use_patch_radius>1</use_patch_radius>
                <ode>
                  <slip>0</slip>
                </ode>
              </torsional>
            </friction>
            <bounce>
              <restitution_coefficient>0</restitution_coefficient>
              <threshold>1e+06</threshold>
            </bounce>
            <contact>
              <collide_without_contact>0</collide_without_contact>
              <collide_without_contact_bitmask>1</collide_without_contact_bitmask>
              <collide_bitmask>1</collide_bitmask>
              <ode>
                <soft_cfm>0</soft_cfm>
                <soft_erp>0.2</soft_erp>
                <kp>1e+13</kp>
                <kd>1</kd>
                <max_vel>0.01</max_vel>
                <min_depth>0</min_depth>
              </ode>
              <bullet>
                <split_impulse>1</split_impulse>
                <split_impulse_penetration_threshold>-0.01</split_impulse_penetration_threshold>
                <soft_cfm>0</soft_cfm>
                <soft_erp>0.2</soft_erp>
                <kp>1e+13</kp>
                <kd>1</kd>
              </bullet>
            </contact>
          </surface>
        </collision>
      </link>
      <joint name='link_0_JOINT_0' type='revolute'>
        <parent>link_0</parent>
        <child>link_1</child>
        <pose frame=''>0 0 0 0 -0 0</pose>
        <axis>
          <xyz>0 0 1</xyz>
          <use_parent_model_frame>0</use_parent_model_frame>
          <limit>
            <lower>-1.79769e+308</lower>
            <upper>1.79769e+308</upper>
            <effort>-1</effort>
            <velocity>-1</velocity>
          </limit>
          <dynamics>
            <spring_reference>0</spring_reference>
            <spring_stiffness>0</spring_stiffness>
            <damping>0</damping>
          </dynamics>
        </axis>
        <physics>
          <ode>
            <limit>
              <cfm>0</cfm>
              <erp>0.2</erp>
            </limit>
            <suspension>
              <cfm>0</cfm>
              <erp>0.2</erp>
            </suspension>
          </ode>
        </physics>
      </joint>
      <joint name='link_0_JOINT_2' type='revolute'>
        <parent>link_0</parent>
        <child>link_1_clone</child>
        <pose frame=''>0 0 0 0 -0 0</pose>
        <axis>
          <xyz>0 0 1</xyz>
          <use_parent_model_frame>0</use_parent_model_frame>
          <limit>
            <lower>-1.79769e+308</lower>
            <upper>1.79769e+308</upper>
            <effort>-1</effort>
            <velocity>-1</velocity>
          </limit>
          <dynamics>
            <spring_reference>0</spring_reference>
            <spring_stiffness>0</spring_stiffness>
            <damping>0</damping>
          </dynamics>
        </axis>
        <physics>
          <ode>
            <limit>
              <cfm>0</cfm>
              <erp>0.2</erp>
            </limit>
            <suspension>
              <cfm>0</cfm>
              <erp>0.2</erp>
            </suspension>
          </ode>
        </physics>
      </joint>
      <joint name='link_0_JOINT_3' type='revolute'>
        <parent>link_0</parent>
        <child>link_1</child>
        <pose frame=''>0 0 0 0 -0 0</pose>
        <axis>
          <xyz>0 0 1</xyz>
          <use_parent_model_frame>0</use_parent_model_frame>
          <limit>
            <lower>-1.79769e+308</lower>
            <upper>1.79769e+308</upper>
            <effort>-1</effort>
            <velocity>-1</velocity>
          </limit>
          <dynamics>
            <spring_reference>0</spring_reference>
            <spring_stiffness>0</spring_stiffness>
            <damping>0</damping>
          </dynamics>
        </axis>
        <physics>
          <ode>
            <limit>
              <cfm>0</cfm>
              <erp>0.2</erp>
            </limit>
            <suspension>
              <cfm>0</cfm>
              <erp>0.2</erp>
            </suspension>
          </ode>
        </physics>
      </joint>
      <joint name='link_0_JOINT_4' type='revolute'>
        <parent>link_0</parent>
        <child>link_1_clone</child>
        <pose frame=''>0 0 0 0 -0 0</pose>
        <axis>
          <xyz>0 0 1</xyz>
          <use_parent_model_frame>0</use_parent_model_frame>
          <limit>
            <lower>-1.79769e+308</lower>
            <upper>1.79769e+308</upper>
            <effort>-1</effort>
            <velocity>-1</velocity>
          </limit>
          <dynamics>
            <spring_reference>0</spring_reference>
            <spring_stiffness>0</spring_stiffness>
            <damping>0</damping>
          </dynamics>
        </axis>
        <physics>
          <ode>
            <limit>
              <cfm>0</cfm>
              <erp>0.2</erp>
            </limit>
            <suspension>
              <cfm>0</cfm>
              <erp>0.2</erp>
            </suspension>
          </ode>
        </physics>
      </joint>
      <joint name='link_0_JOINT_5' type='revolute'>
        <parent>link_0</parent>
        <child>link_4</child>
        <pose frame=''>0 0 0 0 -0 0</pose>
        <axis>
          <xyz>0 0 1</xyz>
          <use_parent_model_frame>0</use_parent_model_frame>
          <limit>
            <lower>-1.79769e+308</lower>
            <upper>1.79769e+308</upper>
            <effort>-1</effort>
            <velocity>-1</velocity>
          </limit>
          <dynamics>
            <spring_reference>0</spring_reference>
            <spring_stiffness>0</spring_stiffness>
            <damping>0</damping>
          </dynamics>
        </axis>
        <physics>
          <ode>
            <limit>
              <cfm>0</cfm>
              <erp>0.2</erp>
            </limit>
            <suspension>
              <cfm>0</cfm>
              <erp>0.2</erp>
            </suspension>
          </ode>
        </physics>
      </joint>
      <joint name='link_4_JOINT_6' type='revolute'>
        <parent>link_4</parent>
        <child>link_5</child>
        <pose frame=''>0 0 0 0 -0 0</pose>
        <axis>
          <xyz>0 0 1</xyz>
          <use_parent_model_frame>0</use_parent_model_frame>
          <limit>
            <lower>-1.79769e+308</lower>
            <upper>1.79769e+308</upper>
            <effort>-1</effort>
            <velocity>-1</velocity>
          </limit>
          <dynamics>
            <spring_reference>0</spring_reference>
            <spring_stiffness>0</spring_stiffness>
            <damping>0</damping>
          </dynamics>
        </axis>
        <physics>
          <ode>
            <limit>
              <cfm>0</cfm>
              <erp>0.2</erp>
            </limit>
            <suspension>
              <cfm>0</cfm>
              <erp>0.2</erp>
            </suspension>
          </ode>
        </physics>
      </joint>
      <static>0</static>
      <allow_auto_disable>1</allow_auto_disable>
      <pose frame=''>0 0 0.43 0 -0 0</pose>
    </model>
    <state world_name='default'>
      <sim_time>383 287000000</sim_time>
      <real_time>28 711458577</real_time>
      <wall_time>1581802441 624274266</wall_time>
      <iterations>16258</iterations>
      <model name='ground_plane'>
        <pose frame=''>0 0 0 0 -0 0</pose>
        <scale>1 1 1</scale>
        <link name='link'>
          <pose frame=''>0 0 0 0 -0 0</pose>
          <velocity>0 0 0 0 -0 0</velocity>
          <acceleration>0 0 0 0 -0 0</acceleration>
          <wrench>0 0 0 0 -0 0</wrench>
        </link>
      </model>
      <model name='mars_rover'>
        <pose frame=''>4.13002 -4.81076 0 0 -0 0</pose>
        <scale>1 1 1</scale>
        <link name='link'>
          <pose frame=''>4.13002 -4.81076 0 0 -0 0</pose>
          <velocity>0 0 0 0 -0 0</velocity>
          <acceleration>0 0 0 0 -0 0</acceleration>
          <wrench>0 0 0 0 -0 0</wrench>
        </link>
      </model>
      <model name='my_ball'>
        <pose frame=''>3.78034 0.721865 0.5 0 -0 0</pose>
        <scale>1 1 1</scale>
        <link name='link_0'>
          <pose frame=''>3.78034 0.721865 0.5 0 -0 0</pose>
          <velocity>0 0 0 0 -0 0</velocity>
          <acceleration>0 0 0 0 -0 0</acceleration>
          <wrench>0 0 0 0 -0 0</wrench>
        </link>
      </model>
      <model name='my_robot'>
        <pose frame=''>-0.000171 5.6e-05 0.124999 -1.7e-05 -4.5e-05 0.001613</pose>
        <scale>1 1 1</scale>
        <link name='left_wheel'>
          <pose frame=''>-0.000413 0.150056 0.124997 -1.9e-05 -2.3e-05 0.001613</pose>
          <velocity>0.001575 0.001922 -0.005342 -0.015697 0.012637 4e-06</velocity>
          <acceleration>0.010484 3.06069 -8.54891 0.29569 0.124214 0.027191</acceleration>
          <wrench>0.052419 15.3035 -42.7446 0 -0 0</wrench>
        </link>
        <link name='right_wheel'>
          <pose frame=''>7.1e-05 -0.149943 0.125002 -1.3e-05 0.001587 0.001613</pose>
          <velocity>0.001579 0.001944 -0.000407 -0.0156 0.012633 -1.2e-05</velocity>
          <acceleration>0.01622 3.09087 -0.646323 0.368114 0.135822 0.03075</acceleration>
          <wrench>0.081102 15.4544 -3.23162 0 -0 0</wrench>
        </link>
        <link name='robot_footprint'>
          <pose frame=''>-0.000171 5.6e-05 0.124999 -1.7e-05 -4.5e-05 0.001613</pose>
          <velocity>0.001585 0.001841 -0.002887 -0.016113 0.012637 -6.5e-05</velocity>
          <acceleration>0.010756 2.89684 -4.62456 -0.656548 0.128369 0.043589</acceleration>
          <wrench>0.162412 43.7423 -69.8309 0 -0 0</wrench>
        </link>
      </model>
      <model name='mybuilding'>
        <pose frame=''>0.24617 -2.27298 0 0 -0 0</pose>
        <scale>1 1 1</scale>
        <link name='Door_0'>
          <pose frame=''>8.05117 1.14202 0 0 -0 0</pose>
          <velocity>0 0 0 0 -0 0</velocity>
          <acceleration>0 0 0 0 -0 0</acceleration>
          <wrench>0 0 0 0 -0 0</wrench>
        </link>
        <link name='Wall_1'>
          <pose frame=''>7.67117 1.72702 0 0 0 -1.5708</pose>
          <velocity>0 0 0 0 -0 0</velocity>
          <acceleration>0 0 0 0 -0 0</acceleration>
          <wrench>0 0 0 0 -0 0</wrench>
        </link>
        <link name='Wall_23'>
          <pose frame=''>0.246175 2.15202 0 0 -0 3.14159</pose>
          <velocity>0 0 0 0 -0 0</velocity>
          <acceleration>0 0 0 0 -0 0</acceleration>
          <wrench>0 0 0 0 -0 0</wrench>
        </link>
        <link name='Wall_25'>
          <pose frame=''>-7.17882 -2.27298 0 0 0 -1.5708</pose>
          <velocity>0 0 0 0 -0 0</velocity>
          <acceleration>0 0 0 0 -0 0</acceleration>
          <wrench>0 0 0 0 -0 0</wrench>
        </link>
        <link name='Wall_26'>
          <pose frame=''>-0.003825 -6.69798 0 0 -0 0</pose>
          <velocity>0 0 0 0 -0 0</velocity>
          <acceleration>0 0 0 0 -0 0</acceleration>
          <wrench>0 0 0 0 -0 0</wrench>
        </link>
        <link name='Wall_27'>
          <pose frame=''>7.17117 -3.89798 0 0 -0 1.5708</pose>
          <velocity>0 0 0 0 -0 0</velocity>
          <acceleration>0 0 0 0 -0 0</acceleration>
          <wrench>0 0 0 0 -0 0</wrench>
        </link>
        <link name='Wall_28'>
          <pose frame=''>4.74618 -1.09798 0 0 -0 3.14159</pose>
          <velocity>0 0 0 0 -0 0</velocity>
          <acceleration>0 0 0 0 -0 0</acceleration>
          <wrench>0 0 0 0 -0 0</wrench>
        </link>
        <link name='Wall_29'>
          <pose frame=''>2.32117 -2.27298 0 0 0 -1.5708</pose>
          <velocity>0 0 0 0 -0 0</velocity>
          <acceleration>0 0 0 0 -0 0</acceleration>
          <wrench>0 0 0 0 -0 0</wrench>
        </link>
        <link name='Wall_30'>
          <pose frame=''>-0.228825 -3.44798 0 0 -0 3.14159</pose>
          <velocity>0 0 0 0 -0 0</velocity>
          <acceleration>0 0 0 0 -0 0</acceleration>
          <wrench>0 0 0 0 -0 0</wrench>
        </link>
        <link name='Wall_41'>
          <pose frame=''>7.64373 -0.229528 0 0 0 -1.5708</pose>
          <velocity>0 0 0 0 -0 0</velocity>
          <acceleration>0 0 0 0 -0 0</acceleration>
          <wrench>0 0 0 0 -0 0</wrench>
        </link>
        <link name='Wall_42'>
          <pose frame=''>2.46873 -0.637988 0 0 -0 3.14159</pose>
          <velocity>0 0 0 0 -0 0</velocity>
          <acceleration>0 0 0 0 -0 0</acceleration>
          <wrench>0 0 0 0 -0 0</wrench>
        </link>
        <link name='Wall_44'>
          <pose frame=''>-2.77883 -2.02298 0 0 -0 1.5708</pose>
          <velocity>0 0 0 0 -0 0</velocity>
          <acceleration>0 0 0 0 -0 0</acceleration>
          <wrench>0 0 0 0 -0 0</wrench>
        </link>
      </model>
      <model name='robot'>
        <pose frame=''>5.59248 0.737497 0.430005 0 -0 0</pose>
        <scale>1 1 1</scale>
        <link name='link_0'>
          <pose frame=''>5.59248 0.737497 0.200005 0 -0 0</pose>
          <velocity>0 0.000532 0.001477 -0.003227 0 0</velocity>
          <acceleration>0 1.06249 2.95437 -0.170672 0 0</acceleration>
          <wrench>0 1.06249 2.95437 0 -0 0</wrench>
        </link>
        <link name='link_1'>
          <pose frame=''>5.59248 0.337478 0.200005 1.5707 -0 0</pose>
          <velocity>0 0.000615 0.002791 -0.003088 0 0</velocity>
          <acceleration>0 1.22816 5.58187 0.107568 -0 0</acceleration>
          <wrench>0 1.22816 5.58187 0 -0 0</wrench>
        </link>
        <link name='link_1_clone'>
          <pose frame=''>5.59248 1.13752 0.200005 1.5707 -0 0</pose>
          <velocity>0 0.00062 0.000147 -0.003101 0 0</velocity>
          <acceleration>0 1.23781 0.29466 0.080709 -0 0</acceleration>
          <wrench>0 1.23781 0.29466 0 -0 0</wrench>
        </link>
        <link name='link_4'>
          <pose frame=''>5.59248 0.737496 0.500005 1e-06 -0 0</pose>
          <velocity>0 0.001461 0.001483 -0.003135 0 0</velocity>
          <acceleration>0 2.92071 2.96573 0.012944 -0 0</acceleration>
          <wrench>0 2.92071 2.96573 0 -0 0</wrench>
        </link>
        <link name='link_5'>
          <pose frame=''>5.59248 0.737496 1.05001 1e-06 -0 0</pose>
          <velocity>0 0.003135 0.001487 -0.003068 0 0</velocity>
          <acceleration>0 6.26887 2.97482 0.146997 -0 0</acceleration>
          <wrench>0 6.26887 2.97482 0 -0 0</wrench>
        </link>
      </model>
      <model name='robot_clone'>
        <pose frame=''>-5.33211 -5.21928 0.430005 0 -0 0</pose>
        <scale>1 1 1</scale>
        <link name='link_0'>
          <pose frame=''>-5.33211 -5.21928 0.200005 0 -0 0</pose>
          <velocity>0 0.000532 0.001477 -0.003227 0 0</velocity>
          <acceleration>0 1.06249 2.95437 -0.170672 0 0</acceleration>
          <wrench>0 1.06249 2.95437 0 -0 0</wrench>
        </link>
        <link name='link_1'>
          <pose frame=''>-5.33211 -5.61929 0.200005 1.5707 -0 0</pose>
          <velocity>0 0.000615 0.002791 -0.003088 0 0</velocity>
          <acceleration>0 1.22816 5.58187 0.107568 -0 0</acceleration>
          <wrench>0 1.22816 5.58187 0 -0 0</wrench>
        </link>
        <link name='link_1_clone'>
          <pose frame=''>-5.33211 -4.81926 0.200005 1.5707 -0 0</pose>
          <velocity>0 0.00062 0.000147 -0.003101 0 0</velocity>
          <acceleration>0 1.23781 0.29466 0.080709 -0 0</acceleration>
          <wrench>0 1.23781 0.29466 0 -0 0</wrench>
        </link>
        <link name='link_4'>
          <pose frame=''>-5.33211 -5.21928 0.500005 1e-06 -0 0</pose>
          <velocity>0 0.001461 0.001483 -0.003135 0 0</velocity>
          <acceleration>0 2.92071 2.96573 0.012944 -0 0</acceleration>
          <wrench>0 2.92071 2.96573 0 -0 0</wrench>
        </link>
        <link name='link_5'>
          <pose frame=''>-5.33211 -5.21928 1.05001 1e-06 -0 0</pose>
          <velocity>0 0.003135 0.001487 -0.003068 0 0</velocity>
          <acceleration>0 6.26887 2.97482 0.146997 -0 0</acceleration>
          <wrench>0 6.26887 2.97482 0 -0 0</wrench>
        </link>
      </model>
      <light name='sun'>
        <pose frame=''>0 0 10 0 -0 0</pose>
      </light>
    </state>
    <gui fullscreen='0'>
      <camera name='user_camera'>
        <pose frame=''>24.0104 0.070125 16.585 0 0.5236 -3.13829</pose>
        <view_controller>orbit</view_controller>
        <projection_type>perspective</projection_type>
      </camera>
    </gui>
    <model name='mybuilding'>
      <pose frame=''>0.466057 -0.833213 0 0 -0 0</pose>
      <link name='Door_0'>
        <collision name='Door_0_Collision'>
          <geometry>
            <box>
              <size>0.9 0.17 2</size>
            </box>
          </geometry>
          <pose frame=''>0 0 1 0 -0 0</pose>
          <max_contacts>10</max_contacts>
          <surface>
            <contact>
              <ode/>
            </contact>
            <bounce/>
            <friction>
              <torsional>
                <ode/>
              </torsional>
              <ode/>
            </friction>
          </surface>
        </collision>
        <visual name='Door_0_Visual'>
          <pose frame=''>0 0 1 0 -0 0</pose>
          <geometry>
            <box>
              <size>0.9 0.17 2</size>
            </box>
          </geometry>
          <material>
            <script>
              <uri>file://media/materials/scripts/gazebo.material</uri>
              <name>Gazebo/Grey</name>
            </script>
          </material>
        </visual>
        <pose frame=''>7.805 3.415 0 0 -0 0</pose>
        <self_collide>0</self_collide>
        <kinematic>0</kinematic>
      </link>
      <link name='Wall_1'>
        <collision name='Wall_1_Collision'>
          <geometry>
            <box>
              <size>1 0.15 2.5</size>
            </box>
          </geometry>
          <pose frame=''>0 0 1.25 0 -0 0</pose>
          <max_contacts>10</max_contacts>
          <surface>
            <contact>
              <ode/>
            </contact>
            <bounce/>
            <friction>
              <torsional>
                <ode/>
              </torsional>
              <ode/>
            </friction>
          </surface>
        </collision>
        <visual name='Wall_1_Visual'>
          <pose frame=''>0 0 1.25 0 -0 0</pose>
          <geometry>
            <box>
              <size>1 0.15 2.5</size>
            </box>
          </geometry>
          <material>
            <script>
              <uri>file://media/materials/scripts/gazebo.material</uri>
              <name>Gazebo/Grey</name>
            </script>
            <ambient>1 0.333333 0 1</ambient>
          </material>
          <meta>
            <layer>0</layer>
          </meta>
        </visual>
        <pose frame=''>7.425 4 0 0 0 -1.5708</pose>
        <self_collide>0</self_collide>
        <kinematic>0</kinematic>
      </link>
      <link name='Wall_23'>
        <collision name='Wall_23_Collision'>
          <geometry>
            <box>
              <size>15 0.15 2.5</size>
            </box>
          </geometry>
          <pose frame=''>0 0 1.25 0 -0 0</pose>
          <max_contacts>10</max_contacts>
          <surface>
            <contact>
              <ode/>
            </contact>
            <bounce/>
            <friction>
              <torsional>
                <ode/>
              </torsional>
              <ode/>
            </friction>
          </surface>
        </collision>
        <visual name='Wall_23_Visual'>
          <pose frame=''>0 0 1.25 0 -0 0</pose>
          <geometry>
            <box>
              <size>15 0.15 2.5</size>
            </box>
          </geometry>
          <material>
            <script>
              <uri>file://media/materials/scripts/gazebo.material</uri>
              <name>Gazebo/Grey</name>
            </script>
            <ambient>1 0.333333 0 1</ambient>
          </material>
          <meta>
            <layer>0</layer>
          </meta>
        </visual>
        <pose frame=''>0 4.425 0 0 -0 3.14159</pose>
        <self_collide>0</self_collide>
        <kinematic>0</kinematic>
      </link>
      <link name='Wall_25'>
        <collision name='Wall_25_Collision'>
          <geometry>
            <box>
              <size>9 0.15 2.5</size>
            </box>
          </geometry>
          <pose frame=''>0 0 1.25 0 -0 0</pose>
          <max_contacts>10</max_contacts>
          <surface>
            <contact>
              <ode/>
            </contact>
            <bounce/>
            <friction>
              <torsional>
                <ode/>
              </torsional>
              <ode/>
            </friction>
          </surface>
        </collision>
        <visual name='Wall_25_Visual'>
          <pose frame=''>0 0 1.25 0 -0 0</pose>
          <geometry>
            <box>
              <size>9 0.15 2.5</size>
            </box>
          </geometry>
          <material>
            <script>
              <uri>file://media/materials/scripts/gazebo.material</uri>
              <name>Gazebo/Grey</name>
            </script>
            <ambient>1 0.333333 0 1</ambient>
          </material>
          <meta>
            <layer>0</layer>
          </meta>
        </visual>
        <pose frame=''>-7.425 0 0 0 0 -1.5708</pose>
        <self_collide>0</self_collide>
        <kinematic>0</kinematic>
      </link>
      <link name='Wall_26'>
        <collision name='Wall_26_Collision'>
          <geometry>
            <box>
              <size>14.5 0.15 2.5</size>
            </box>
          </geometry>
          <pose frame=''>0 0 1.25 0 -0 0</pose>
          <max_contacts>10</max_contacts>
          <surface>
            <contact>
              <ode/>
            </contact>
            <bounce/>
            <friction>
              <torsional>
                <ode/>
              </torsional>
              <ode/>
            </friction>
          </surface>
        </collision>
        <visual name='Wall_26_Visual'>
          <pose frame=''>0 0 1.25 0 -0 0</pose>
          <geometry>
            <box>
              <size>14.5 0.15 2.5</size>
            </box>
          </geometry>
          <material>
            <script>
              <uri>file://media/materials/scripts/gazebo.material</uri>
              <name>Gazebo/Grey</name>
            </script>
            <ambient>1 0.333333 0 1</ambient>
          </material>
          <meta>
            <layer>0</layer>
          </meta>
        </visual>
        <pose frame=''>-0.25 -4.425 0 0 -0 0</pose>
        <self_collide>0</self_collide>
        <kinematic>0</kinematic>
      </link>
      <link name='Wall_27'>
        <collision name='Wall_27_Collision'>
          <geometry>
            <box>
              <size>5.75 0.15 2.5</size>
            </box>
          </geometry>
          <pose frame=''>0 0 1.25 0 -0 0</pose>
          <max_contacts>10</max_contacts>
          <surface>
            <contact>
              <ode/>
            </contact>
            <bounce/>
            <friction>
              <torsional>
                <ode/>
              </torsional>
              <ode/>
            </friction>
          </surface>
        </collision>
        <visual name='Wall_27_Visual'>
          <pose frame=''>0 0 1.25 0 -0 0</pose>
          <geometry>
            <box>
              <size>5.75 0.15 2.5</size>
            </box>
          </geometry>
          <material>
            <script>
              <uri>file://media/materials/scripts/gazebo.material</uri>
              <name>Gazebo/Grey</name>
            </script>
            <ambient>1 0.333333 0 1</ambient>
          </material>
          <meta>
            <layer>0</layer>
          </meta>
        </visual>
        <pose frame=''>6.925 -1.625 0 0 -0 1.5708</pose>
        <self_collide>0</self_collide>
        <kinematic>0</kinematic>
      </link>
      <link name='Wall_28'>
        <collision name='Wall_28_Collision'>
          <geometry>
            <box>
              <size>5 0.15 2.5</size>
            </box>
          </geometry>
          <pose frame=''>0 0 1.25 0 -0 0</pose>
          <max_contacts>10</max_contacts>
          <surface>
            <contact>
              <ode/>
            </contact>
            <bounce/>
            <friction>
              <torsional>
                <ode/>
              </torsional>
              <ode/>
            </friction>
          </surface>
        </collision>
        <visual name='Wall_28_Visual'>
          <pose frame=''>0 0 1.25 0 -0 0</pose>
          <geometry>
            <box>
              <size>5 0.15 2.5</size>
            </box>
          </geometry>
          <material>
            <script>
              <uri>file://media/materials/scripts/gazebo.material</uri>
              <name>Gazebo/Grey</name>
            </script>
            <ambient>1 0.333333 0 1</ambient>
          </material>
          <meta>
            <layer>0</layer>
          </meta>
        </visual>
        <pose frame=''>4.5 1.175 0 0 -0 3.14159</pose>
        <self_collide>0</self_collide>
        <kinematic>0</kinematic>
      </link>
      <link name='Wall_29'>
        <collision name='Wall_29_Collision'>
          <geometry>
            <box>
              <size>2.5 0.15 2.5</size>
            </box>
          </geometry>
          <pose frame=''>0 0 1.25 0 -0 0</pose>
          <max_contacts>10</max_contacts>
          <surface>
            <contact>
              <ode/>
            </contact>
            <bounce/>
            <friction>
              <torsional>
                <ode/>
              </torsional>
              <ode/>
            </friction>
          </surface>
        </collision>
        <visual name='Wall_29_Visual'>
          <pose frame=''>0 0 1.25 0 -0 0</pose>
          <geometry>
            <box>
              <size>2.5 0.15 2.5</size>
            </box>
          </geometry>
          <material>
            <script>
              <uri>file://media/materials/scripts/gazebo.material</uri>
              <name>Gazebo/Grey</name>
            </script>
            <ambient>1 0.333333 0 1</ambient>
          </material>
          <meta>
            <layer>0</layer>
          </meta>
        </visual>
        <pose frame=''>2.075 0 0 0 0 -1.5708</pose>
        <self_collide>0</self_collide>
        <kinematic>0</kinematic>
      </link>
      <link name='Wall_30'>
        <collision name='Wall_30_Collision'>
          <geometry>
            <box>
              <size>5.25 0.15 2.5</size>
            </box>
          </geometry>
          <pose frame=''>0 0 1.25 0 -0 0</pose>
          <max_contacts>10</max_contacts>
          <surface>
            <contact>
              <ode/>
            </contact>
            <bounce/>
            <friction>
              <torsional>
                <ode/>
              </torsional>
              <ode/>
            </friction>
          </surface>
        </collision>
        <visual name='Wall_30_Visual'>
          <pose frame=''>0 0 1.25 0 -0 0</pose>
          <geometry>
            <box>
              <size>5.25 0.15 2.5</size>
            </box>
          </geometry>
          <material>
            <script>
              <uri>file://media/materials/scripts/gazebo.material</uri>
              <name>Gazebo/Grey</name>
            </script>
            <ambient>1 0.333333 0 1</ambient>
          </material>
          <meta>
            <layer>0</layer>
          </meta>
        </visual>
        <pose frame=''>-0.475 -1.175 0 0 -0 3.14159</pose>
        <self_collide>0</self_collide>
        <kinematic>0</kinematic>
      </link>
      <link name='Wall_41'>
        <collision name='Wall_41_Collision'>
          <geometry>
            <box>
              <size>0.940974 0.15 2.5</size>
            </box>
          </geometry>
          <pose frame=''>0 0 1.25 0 -0 0</pose>
          <max_contacts>10</max_contacts>
          <surface>
            <contact>
              <ode/>
            </contact>
            <bounce/>
            <friction>
              <torsional>
                <ode/>
              </torsional>
              <ode/>
            </friction>
          </surface>
        </collision>
        <visual name='Wall_41_Visual'>
          <pose frame=''>0 0 1.25 0 -0 0</pose>
          <geometry>
            <box>
              <size>0.940974 0.15 2.5</size>
            </box>
          </geometry>
          <material>
            <script>
              <uri>file://media/materials/scripts/gazebo.material</uri>
              <name>Gazebo/Grey</name>
            </script>
            <ambient>1 0.333333 0 1</ambient>
          </material>
          <meta>
            <layer>0</layer>
          </meta>
        </visual>
        <pose frame=''>7.39756 2.04345 0 0 0 -1.5708</pose>
        <self_collide>0</self_collide>
        <kinematic>0</kinematic>
      </link>
      <link name='Wall_42'>
        <collision name='Wall_42_Collision'>
          <geometry>
            <box>
              <size>10.5 0.15 2.5</size>
            </box>
          </geometry>
          <pose frame=''>0 0 1.25 0 -0 0</pose>
          <max_contacts>10</max_contacts>
          <surface>
            <contact>
              <ode/>
            </contact>
            <bounce/>
            <friction>
              <torsional>
                <ode/>
              </torsional>
              <ode/>
            </friction>
          </surface>
        </collision>
        <visual name='Wall_42_Visual'>
          <pose frame=''>0 0 1.25 0 -0 0</pose>
          <geometry>
            <box>
              <size>10.5 0.15 2.5</size>
            </box>
          </geometry>
          <material>
            <script>
              <uri>file://media/materials/scripts/gazebo.material</uri>
              <name>Gazebo/Grey</name>
            </script>
            <ambient>1 0.333333 0 1</ambient>
          </material>
          <meta>
            <layer>0</layer>
          </meta>
        </visual>
        <pose frame=''>2.22256 1.63499 0 0 -0 3.14159</pose>
        <self_collide>0</self_collide>
        <kinematic>0</kinematic>
      </link>
      <link name='Wall_44'>
        <collision name='Wall_44_Collision'>
          <geometry>
            <box>
              <size>3 0.15 2.5</size>
            </box>
          </geometry>
          <pose frame=''>0 0 1.25 0 -0 0</pose>
          <max_contacts>10</max_contacts>
          <surface>
            <contact>
              <ode/>
            </contact>
            <bounce/>
            <friction>
              <torsional>
                <ode/>
              </torsional>
              <ode/>
            </friction>
          </surface>
        </collision>
        <visual name='Wall_44_Visual'>
          <pose frame=''>0 0 1.25 0 -0 0</pose>
          <geometry>
            <box>
              <size>3 0.15 2.5</size>
            </box>
          </geometry>
          <material>
            <script>
              <uri>file://media/materials/scripts/gazebo.material</uri>
              <name>Gazebo/Grey</name>
            </script>
            <ambient>1 0.333333 0 1</ambient>
          </material>
          <meta>
            <layer>0</layer>
          </meta>
        </visual>
        <pose frame=''>-3.025 0.25 0 0 -0 1.5708</pose>
        <self_collide>0</self_collide>
        <kinematic>0</kinematic>
      </link>
      <static>1</static>
    </model>
    <model name='mars_rover'>
      <static>1</static>
      <link name='link'>
        <collision name='solar_panel_collision'>
          <pose frame=''>0 -0.06945 0.47293 0 -0 0</pose>
          <geometry>
            <box>
              <size>0.87974 0.8821 0.02602</size>
            </box>
          </geometry>
          <max_contacts>10</max_contacts>
          <surface>
            <contact>
              <ode/>
            </contact>
            <bounce/>
            <friction>
              <torsional>
                <ode/>
              </torsional>
              <ode/>
            </friction>
          </surface>
        </collision>
        <collision name='chassis_collision'>
          <pose frame=''>0 -0.05 0.31475 0 -0 0</pose>
          <geometry>
            <box>
              <size>0.49522 0.67401 0.28915</size>
            </box>
          </geometry>
          <max_contacts>10</max_contacts>
          <surface>
            <contact>
              <ode/>
            </contact>
            <bounce/>
            <friction>
              <torsional>
                <ode/>
              </torsional>
              <ode/>
            </friction>
          </surface>
        </collision>
        <collision name='rear_left_bumper_collision'>
          <pose frame=''>0.30107 0.3835 0.38976 0 -0 0</pose>
          <geometry>
            <box>
              <size>0.04442 0.38897 0.07918</size>
            </box>
          </geometry>
          <max_contacts>10</max_contacts>
          <surface>
            <contact>
              <ode/>
            </contact>
            <bounce/>
            <friction>
              <torsional>
                <ode/>
              </torsional>
              <ode/>
            </friction>
          </surface>
        </collision>
        <collision name='rear_right_bumper_collision'>
          <pose frame=''>-0.30107 0.3835 0.38976 0 -0 0</pose>
          <geometry>
            <box>
              <size>0.04442 0.38897 0.07918</size>
            </box>
          </geometry>
          <max_contacts>10</max_contacts>
          <surface>
            <contact>
              <ode/>
            </contact>
            <bounce/>
            <friction>
              <torsional>
                <ode/>
              </torsional>
              <ode/>
            </friction>
          </surface>
        </collision>
        <collision name='rear_bumper_collision'>
          <pose frame=''>0 0.59414 0.38976 0 -0 0</pose>
          <geometry>
            <box>
              <size>0.56656 0.04442 0.07918</size>
            </box>
          </geometry>
          <max_contacts>10</max_contacts>
          <surface>
            <contact>
              <ode/>
            </contact>
            <bounce/>
            <friction>
              <torsional>
                <ode/>
              </torsional>
              <ode/>
            </friction>
          </surface>
        </collision>
        <collision name='bin_back_panel_collision'>
          <pose frame=''>0 0.47 0.32114 0.69137 -0 0</pose>
          <geometry>
            <box>
              <size>0.43774 0.212366 0.05173</size>
            </box>
          </geometry>
          <max_contacts>10</max_contacts>
          <surface>
            <contact>
              <ode/>
            </contact>
            <bounce/>
            <friction>
              <torsional>
                <ode/>
              </torsional>
              <ode/>
            </friction>
          </surface>
        </collision>
        <collision name='bin_left_panel_collision1'>
          <pose frame=''>0.22615 0.32897 0.33193 0 -0 0</pose>
          <geometry>
            <box>
              <size>0.01116 0.19338 0.16304</size>
            </box>
          </geometry>
          <max_contacts>10</max_contacts>
          <surface>
            <contact>
              <ode/>
            </contact>
            <bounce/>
            <friction>
              <torsional>
                <ode/>
              </torsional>
              <ode/>
            </friction>
          </surface>
        </collision>
        <collision name='bin_left_panel_collision2'>
          <pose frame=''>0.22615 0.471 0.39308 0 -0 0</pose>
          <geometry>
            <box>
              <size>0.01116 0.15 0.04</size>
            </box>
          </geometry>
          <max_contacts>10</max_contacts>
          <surface>
            <contact>
              <ode/>
            </contact>
            <bounce/>
            <friction>
              <torsional>
                <ode/>
              </torsional>
              <ode/>
            </friction>
          </surface>
        </collision>
        <collision name='bin_left_panel_collision3'>
          <pose frame=''>0.22615 0.45 0.35308 0 -0 0</pose>
          <geometry>
            <box>
              <size>0.01116 0.15 0.04</size>
            </box>
          </geometry>
          <max_contacts>10</max_contacts>
          <surface>
            <contact>
              <ode/>
            </contact>
            <bounce/>
            <friction>
              <torsional>
                <ode/>
              </torsional>
              <ode/>
            </friction>
          </surface>
        </collision>
        <collision name='bin_left_panel_collision4'>
          <pose frame=''>0.22615 0.39308 0.31308 0 -0 0</pose>
          <geometry>
            <box>
              <size>0.01116 0.15 0.04</size>
            </box>
          </geometry>
          <max_contacts>10</max_contacts>
          <surface>
            <contact>
              <ode/>
            </contact>
            <bounce/>
            <friction>
              <torsional>
                <ode/>
              </torsional>
              <ode/>
            </friction>
          </surface>
        </collision>
        <collision name='bin_right_panel_collision1'>
          <pose frame=''>-0.22615 0.32897 0.33193 0 -0 0</pose>
          <geometry>
            <box>
              <size>0.01116 0.19338 0.16304</size>
            </box>
          </geometry>
          <max_contacts>10</max_contacts>
          <surface>
            <contact>
              <ode/>
            </contact>
            <bounce/>
            <friction>
              <torsional>
                <ode/>
              </torsional>
              <ode/>
            </friction>
          </surface>
        </collision>
        <collision name='bin_right_panel_collision2'>
          <pose frame=''>-0.22615 0.471 0.39308 0 -0 0</pose>
          <geometry>
            <box>
              <size>0.01116 0.15 0.04</size>
            </box>
          </geometry>
          <max_contacts>10</max_contacts>
          <surface>
            <contact>
              <ode/>
            </contact>
            <bounce/>
            <friction>
              <torsional>
                <ode/>
              </torsional>
              <ode/>
            </friction>
          </surface>
        </collision>
        <collision name='bin_right_panel_collision3'>
          <pose frame=''>-0.22615 0.45 0.35308 0 -0 0</pose>
          <geometry>
            <box>
              <size>0.01116 0.15 0.04</size>
            </box>
          </geometry>
          <max_contacts>10</max_contacts>
          <surface>
            <contact>
              <ode/>
            </contact>
            <bounce/>
            <friction>
              <torsional>
                <ode/>
              </torsional>
              <ode/>
            </friction>
          </surface>
        </collision>
        <collision name='bin_right_panel_collision4'>
          <pose frame=''>-0.22615 0.39308 0.31308 0 -0 0</pose>
          <geometry>
            <box>
              <size>0.01116 0.15 0.04</size>
            </box>
          </geometry>
          <max_contacts>10</max_contacts>
          <surface>
            <contact>
              <ode/>
            </contact>
            <bounce/>
            <friction>
              <torsional>
                <ode/>
              </torsional>
              <ode/>
            </friction>
          </surface>
        </collision>
        <collision name='bin_front_panel_collision'>
          <pose frame=''>0 0.30047 0.32114 2.26207 -0 0</pose>
          <geometry>
            <box>
              <size>0.43774 0.212366 0.05173</size>
            </box>
          </geometry>
          <max_contacts>10</max_contacts>
          <surface>
            <contact>
              <ode/>
            </contact>
            <bounce/>
            <friction>
              <torsional>
                <ode/>
              </torsional>
              <ode/>
            </friction>
          </surface>
        </collision>
        <collision name='front_left_wheel_collision'>
          <pose frame=''>0.31103 -0.32115 0.1358 1.5707 0 1.5707</pose>
          <geometry>
            <cylinder>
              <radius>0.1358</radius>
              <length>0.1641</length>
            </cylinder>
          </geometry>
          <max_contacts>10</max_contacts>
          <surface>
            <contact>
              <ode/>
            </contact>
            <bounce/>
            <friction>
              <torsional>
                <ode/>
              </torsional>
              <ode/>
            </friction>
          </surface>
        </collision>
        <collision name='front_right_wheel_collision'>
          <pose frame=''>-0.31103 -0.32115 0.1358 1.5707 0 1.5707</pose>
          <geometry>
            <cylinder>
              <radius>0.1358</radius>
              <length>0.1641</length>
            </cylinder>
          </geometry>
          <max_contacts>10</max_contacts>
          <surface>
            <contact>
              <ode/>
            </contact>
            <bounce/>
            <friction>
              <torsional>
                <ode/>
              </torsional>
              <ode/>
            </friction>
          </surface>
        </collision>
        <collision name='rear_left_wheel_collision'>
          <pose frame=''>0.31103 0.28049 0.1358 1.5707 0 1.5707</pose>
          <geometry>
            <cylinder>
              <radius>0.1358</radius>
              <length>0.1641</length>
            </cylinder>
          </geometry>
          <max_contacts>10</max_contacts>
          <surface>
            <contact>
              <ode/>
            </contact>
            <bounce/>
            <friction>
              <torsional>
                <ode/>
              </torsional>
              <ode/>
            </friction>
          </surface>
        </collision>
        <collision name='rear_right_wheel_collision'>
          <pose frame=''>-0.31103 0.28049 0.1358 1.5707 0 1.5707</pose>
          <geometry>
            <cylinder>
              <radius>0.1358</radius>
              <length>0.1641</length>
            </cylinder>
          </geometry>
          <max_contacts>10</max_contacts>
          <surface>
            <contact>
              <ode/>
            </contact>
            <bounce/>
            <friction>
              <torsional>
                <ode/>
              </torsional>
              <ode/>
            </friction>
          </surface>
        </collision>
        <visual name='visual'>
          <geometry>
            <mesh>
              <uri>model://mars_rover/meshes/rover.dae</uri>
            </mesh>
          </geometry>
        </visual>
        <self_collide>0</self_collide>
        <kinematic>0</kinematic>
      </link>
      <pose frame=''>4.10517 -2.11772 0 0 -0 0</pose>
    </model>
    <model name='robot_clone'>
      <link name='link_0'>
        <pose frame=''>0 0 -0.23 0 -0 0</pose>
        <inertial>
          <mass>1</mass>
          <inertia>
            <ixx>0.166667</ixx>
            <ixy>0</ixy>
            <ixz>0</ixz>
            <iyy>0.166667</iyy>
            <iyz>0</iyz>
            <izz>0.166667</izz>
          </inertia>
          <pose frame=''>0 0 0 0 -0 0</pose>
        </inertial>
        <gravity>1</gravity>
        <self_collide>0</self_collide>
        <kinematic>0</kinematic>
        <visual name='visual'>
          <pose frame=''>0 0 0 0 -0 0</pose>
          <geometry>
            <box>
              <size>0.5 0.7 0.1</size>
            </box>
          </geometry>
          <material>
            <lighting>1</lighting>
            <script>
              <uri>file://media/materials/scripts/gazebo.material</uri>
              <name>Gazebo/Grey</name>
            </script>
            <shader type='pixel'>
              <normal_map>__default__</normal_map>
            </shader>
            <ambient>0.3 0.3 0.3 1</ambient>
            <diffuse>0.7 0.7 0.7 1</diffuse>
            <specular>0.01 0.01 0.01 1</specular>
            <emissive>0 0 0 1</emissive>
          </material>
          <transparency>0</transparency>
          <cast_shadows>1</cast_shadows>
        </visual>
        <collision name='collision'>
          <laser_retro>0</laser_retro>
          <max_contacts>10</max_contacts>
          <pose frame=''>0 0 0 0 -0 0</pose>
          <geometry>
            <box>
              <size>0.5 0.7 0.1</size>
            </box>
          </geometry>
          <surface>
            <friction>
              <ode>
                <mu>1</mu>
                <mu2>1</mu2>
                <fdir1>0 0 0</fdir1>
                <slip1>0</slip1>
                <slip2>0</slip2>
              </ode>
              <torsional>
                <coefficient>1</coefficient>
                <patch_radius>0</patch_radius>
                <surface_radius>0</surface_radius>
                <use_patch_radius>1</use_patch_radius>
                <ode>
                  <slip>0</slip>
                </ode>
              </torsional>
            </friction>
            <bounce>
              <restitution_coefficient>0</restitution_coefficient>
              <threshold>1e+06</threshold>
            </bounce>
            <contact>
              <collide_without_contact>0</collide_without_contact>
              <collide_without_contact_bitmask>1</collide_without_contact_bitmask>
              <collide_bitmask>1</collide_bitmask>
              <ode>
                <soft_cfm>0</soft_cfm>
                <soft_erp>0.2</soft_erp>
                <kp>1e+13</kp>
                <kd>1</kd>
                <max_vel>0.01</max_vel>
                <min_depth>0</min_depth>
              </ode>
              <bullet>
                <split_impulse>1</split_impulse>
                <split_impulse_penetration_threshold>-0.01</split_impulse_penetration_threshold>
                <soft_cfm>0</soft_cfm>
                <soft_erp>0.2</soft_erp>
                <kp>1e+13</kp>
                <kd>1</kd>
              </bullet>
            </contact>
          </surface>
        </collision>
      </link>
      <link name='link_1'>
        <pose frame=''>0 -0.400019 -0.23 1.5707 -0 0</pose>
        <inertial>
          <mass>1</mass>
          <inertia>
            <ixx>0.145833</ixx>
            <ixy>0</ixy>
            <ixz>0</ixz>
            <iyy>0.145833</iyy>
            <iyz>0</iyz>
            <izz>0.125</izz>
          </inertia>
          <pose frame=''>0 0 0 0 -0 0</pose>
        </inertial>
        <gravity>1</gravity>
        <self_collide>0</self_collide>
        <kinematic>0</kinematic>
        <visual name='visual'>
          <pose frame=''>0 0 0 0 -0 0</pose>
          <geometry>
            <cylinder>
              <radius>0.2</radius>
              <length>0.1</length>
            </cylinder>
          </geometry>
          <material>
            <lighting>1</lighting>
            <script>
              <uri>file://media/materials/scripts/gazebo.material</uri>
              <name>Gazebo/Grey</name>
            </script>
            <shader type='pixel'>
              <normal_map>__default__</normal_map>
            </shader>
            <ambient>0.3 0.3 0.3 1</ambient>
            <diffuse>0.7 0.7 0.7 1</diffuse>
            <specular>0.01 0.01 0.01 1</specular>
            <emissive>0 0 0 1</emissive>
          </material>
          <transparency>0</transparency>
          <cast_shadows>1</cast_shadows>
        </visual>
        <collision name='collision'>
          <laser_retro>0</laser_retro>
          <max_contacts>10</max_contacts>
          <pose frame=''>0 0 0 0 -0 0</pose>
          <geometry>
            <cylinder>
              <radius>0.2</radius>
              <length>0.1</length>
            </cylinder>
          </geometry>
          <surface>
            <friction>
              <ode>
                <mu>1</mu>
                <mu2>1</mu2>
                <fdir1>0 0 0</fdir1>
                <slip1>0</slip1>
                <slip2>0</slip2>
              </ode>
              <torsional>
                <coefficient>1</coefficient>
                <patch_radius>0</patch_radius>
                <surface_radius>0</surface_radius>
                <use_patch_radius>1</use_patch_radius>
                <ode>
                  <slip>0</slip>
                </ode>
              </torsional>
            </friction>
            <bounce>
              <restitution_coefficient>0</restitution_coefficient>
              <threshold>1e+06</threshold>
            </bounce>
            <contact>
              <collide_without_contact>0</collide_without_contact>
              <collide_without_contact_bitmask>1</collide_without_contact_bitmask>
              <collide_bitmask>1</collide_bitmask>
              <ode>
                <soft_cfm>0</soft_cfm>
                <soft_erp>0.2</soft_erp>
                <kp>1e+13</kp>
                <kd>1</kd>
                <max_vel>0.01</max_vel>
                <min_depth>0</min_depth>
              </ode>
              <bullet>
                <split_impulse>1</split_impulse>
                <split_impulse_penetration_threshold>-0.01</split_impulse_penetration_threshold>
                <soft_cfm>0</soft_cfm>
                <soft_erp>0.2</soft_erp>
                <kp>1e+13</kp>
                <kd>1</kd>
              </bullet>
            </contact>
          </surface>
        </collision>
      </link>
      <link name='link_1_clone'>
        <pose frame=''>0 0.400019 -0.23 1.5707 -0 0</pose>
        <inertial>
          <mass>1</mass>
          <inertia>
            <ixx>0.145833</ixx>
            <ixy>0</ixy>
            <ixz>0</ixz>
            <iyy>0.145833</iyy>
            <iyz>0</iyz>
            <izz>0.125</izz>
          </inertia>
          <pose frame=''>0 0 0 0 -0 0</pose>
        </inertial>
        <self_collide>0</self_collide>
        <kinematic>0</kinematic>
        <visual name='visual'>
          <pose frame=''>0 0 0 0 -0 0</pose>
          <geometry>
            <cylinder>
              <radius>0.2</radius>
              <length>0.1</length>
            </cylinder>
          </geometry>
          <material>
            <lighting>1</lighting>
            <script>
              <uri>file://media/materials/scripts/gazebo.material</uri>
              <name>Gazebo/Grey</name>
            </script>
            <shader type='pixel'>
              <normal_map>__default__</normal_map>
            </shader>
            <ambient>0.3 0.3 0.3 1</ambient>
            <diffuse>0.7 0.7 0.7 1</diffuse>
            <specular>0.01 0.01 0.01 1</specular>
            <emissive>0 0 0 1</emissive>
          </material>
          <transparency>0</transparency>
          <cast_shadows>1</cast_shadows>
        </visual>
        <collision name='collision'>
          <laser_retro>0</laser_retro>
          <max_contacts>10</max_contacts>
          <pose frame=''>0 0 0 0 -0 0</pose>
          <geometry>
            <cylinder>
              <radius>0.2</radius>
              <length>0.1</length>
            </cylinder>
          </geometry>
          <surface>
            <friction>
              <ode>
                <mu>1</mu>
                <mu2>1</mu2>
                <fdir1>0 0 0</fdir1>
                <slip1>0</slip1>
                <slip2>0</slip2>
              </ode>
              <torsional>
                <coefficient>1</coefficient>
                <patch_radius>0</patch_radius>
                <surface_radius>0</surface_radius>
                <use_patch_radius>1</use_patch_radius>
                <ode>
                  <slip>0</slip>
                </ode>
              </torsional>
            </friction>
            <bounce>
              <restitution_coefficient>0</restitution_coefficient>
              <threshold>1e+06</threshold>
            </bounce>
            <contact>
              <collide_without_contact>0</collide_without_contact>
              <collide_without_contact_bitmask>1</collide_without_contact_bitmask>
              <collide_bitmask>1</collide_bitmask>
              <ode>
                <soft_cfm>0</soft_cfm>
                <soft_erp>0.2</soft_erp>
                <kp>1e+13</kp>
                <kd>1</kd>
                <max_vel>0.01</max_vel>
                <min_depth>0</min_depth>
              </ode>
              <bullet>
                <split_impulse>1</split_impulse>
                <split_impulse_penetration_threshold>-0.01</split_impulse_penetration_threshold>
                <soft_cfm>0</soft_cfm>
                <soft_erp>0.2</soft_erp>
                <kp>1e+13</kp>
                <kd>1</kd>
              </bullet>
            </contact>
          </surface>
        </collision>
      </link>
      <link name='link_4'>
        <pose frame=''>0 0 0.07 0 -0 0</pose>
        <inertial>
          <mass>1</mass>
          <inertia>
            <ixx>0.166667</ixx>
            <ixy>0</ixy>
            <ixz>0</ixz>
            <iyy>0.166667</iyy>
            <iyz>0</iyz>
            <izz>0.166667</izz>
          </inertia>
          <pose frame=''>0 0 0 0 -0 0</pose>
        </inertial>
        <gravity>1</gravity>
        <self_collide>0</self_collide>
        <kinematic>0</kinematic>
        <visual name='visual'>
          <pose frame=''>0 0 0 0 -0 0</pose>
          <geometry>
            <box>
              <size>0.4 0.5 0.7</size>
            </box>
          </geometry>
          <material>
            <lighting>1</lighting>
            <script>
              <uri>file://media/materials/scripts/gazebo.material</uri>
              <name>Gazebo/Grey</name>
            </script>
            <shader type='pixel'>
              <normal_map>__default__</normal_map>
            </shader>
            <ambient>0.3 0.3 0.3 1</ambient>
            <diffuse>0.7 0.7 0.7 1</diffuse>
            <specular>0.01 0.01 0.01 1</specular>
            <emissive>0 0 0 1</emissive>
          </material>
          <transparency>0</transparency>
          <cast_shadows>1</cast_shadows>
        </visual>
        <collision name='collision'>
          <laser_retro>0</laser_retro>
          <max_contacts>10</max_contacts>
          <pose frame=''>0 0 0 0 -0 0</pose>
          <geometry>
            <box>
              <size>0.4 0.5 0.7</size>
            </box>
          </geometry>
          <surface>
            <friction>
              <ode>
                <mu>1</mu>
                <mu2>1</mu2>
                <fdir1>0 0 0</fdir1>
                <slip1>0</slip1>
                <slip2>0</slip2>
              </ode>
              <torsional>
                <coefficient>1</coefficient>
                <patch_radius>0</patch_radius>
                <surface_radius>0</surface_radius>
                <use_patch_radius>1</use_patch_radius>
                <ode>
                  <slip>0</slip>
                </ode>
              </torsional>
            </friction>
            <bounce>
              <restitution_coefficient>0</restitution_coefficient>
              <threshold>1e+06</threshold>
            </bounce>
            <contact>
              <collide_without_contact>0</collide_without_contact>
              <collide_without_contact_bitmask>1</collide_without_contact_bitmask>
              <collide_bitmask>1</collide_bitmask>
              <ode>
                <soft_cfm>0</soft_cfm>
                <soft_erp>0.2</soft_erp>
                <kp>1e+13</kp>
                <kd>1</kd>
                <max_vel>0.01</max_vel>
                <min_depth>0</min_depth>
              </ode>
              <bullet>
                <split_impulse>1</split_impulse>
                <split_impulse_penetration_threshold>-0.01</split_impulse_penetration_threshold>
                <soft_cfm>0</soft_cfm>
                <soft_erp>0.2</soft_erp>
                <kp>1e+13</kp>
                <kd>1</kd>
              </bullet>
            </contact>
          </surface>
        </collision>
      </link>
      <link name='link_5'>
        <pose frame=''>0 0 0.62 0 -0 0</pose>
        <inertial>
          <mass>1</mass>
          <inertia>
            <ixx>0.1</ixx>
            <ixy>0</ixy>
            <ixz>0</ixz>
            <iyy>0.1</iyy>
            <iyz>0</iyz>
            <izz>0.1</izz>
          </inertia>
          <pose frame=''>0 0 0 0 -0 0</pose>
        </inertial>
        <gravity>1</gravity>
        <self_collide>0</self_collide>
        <kinematic>0</kinematic>
        <visual name='visual'>
          <pose frame=''>0 0 0 0 -0 0</pose>
          <geometry>
            <sphere>
              <radius>0.2</radius>
            </sphere>
          </geometry>
          <material>
            <lighting>1</lighting>
            <script>
              <uri>file://media/materials/scripts/gazebo.material</uri>
              <name>Gazebo/Grey</name>
            </script>
            <shader type='pixel'>
              <normal_map>__default__</normal_map>
            </shader>
            <ambient>0.3 0.3 0.3 1</ambient>
            <diffuse>0.7 0.7 0.7 1</diffuse>
            <specular>0.01 0.01 0.01 1</specular>
            <emissive>0 0 0 1</emissive>
          </material>
          <transparency>0</transparency>
          <cast_shadows>1</cast_shadows>
        </visual>
        <collision name='collision'>
          <laser_retro>0</laser_retro>
          <max_contacts>10</max_contacts>
          <pose frame=''>0 0 0 0 -0 0</pose>
          <geometry>
            <sphere>
              <radius>0.2</radius>
            </sphere>
          </geometry>
          <surface>
            <friction>
              <ode>
                <mu>1</mu>
                <mu2>1</mu2>
                <fdir1>0 0 0</fdir1>
                <slip1>0</slip1>
                <slip2>0</slip2>
              </ode>
              <torsional>
                <coefficient>1</coefficient>
                <patch_radius>0</patch_radius>
                <surface_radius>0</surface_radius>
                <use_patch_radius>1</use_patch_radius>
                <ode>
                  <slip>0</slip>
                </ode>
              </torsional>
            </friction>
            <bounce>
              <restitution_coefficient>0</restitution_coefficient>
              <threshold>1e+06</threshold>
            </bounce>
            <contact>
              <collide_without_contact>0</collide_without_contact>
              <collide_without_contact_bitmask>1</collide_without_contact_bitmask>
              <collide_bitmask>1</collide_bitmask>
              <ode>
                <soft_cfm>0</soft_cfm>
                <soft_erp>0.2</soft_erp>
                <kp>1e+13</kp>
                <kd>1</kd>
                <max_vel>0.01</max_vel>
                <min_depth>0</min_depth>
              </ode>
              <bullet>
                <split_impulse>1</split_impulse>
                <split_impulse_penetration_threshold>-0.01</split_impulse_penetration_threshold>
                <soft_cfm>0</soft_cfm>
                <soft_erp>0.2</soft_erp>
                <kp>1e+13</kp>
                <kd>1</kd>
              </bullet>
            </contact>
          </surface>
        </collision>
      </link>
      <joint name='link_0_JOINT_0' type='revolute'>
        <parent>link_0</parent>
        <child>link_1</child>
        <pose frame=''>0 0 0 0 -0 0</pose>
        <axis>
          <xyz>0 0 1</xyz>
          <use_parent_model_frame>0</use_parent_model_frame>
          <limit>
            <lower>-1.79769e+308</lower>
            <upper>1.79769e+308</upper>
            <effort>-1</effort>
            <velocity>-1</velocity>
          </limit>
          <dynamics>
            <spring_reference>0</spring_reference>
            <spring_stiffness>0</spring_stiffness>
            <damping>0</damping>
          </dynamics>
        </axis>
        <physics>
          <ode>
            <limit>
              <cfm>0</cfm>
              <erp>0.2</erp>
            </limit>
            <suspension>
              <cfm>0</cfm>
              <erp>0.2</erp>
            </suspension>
          </ode>
        </physics>
      </joint>
      <joint name='link_0_JOINT_2' type='revolute'>
        <parent>link_0</parent>
        <child>link_1_clone</child>
        <pose frame=''>0 0 0 0 -0 0</pose>
        <axis>
          <xyz>0 0 1</xyz>
          <use_parent_model_frame>0</use_parent_model_frame>
          <limit>
            <lower>-1.79769e+308</lower>
            <upper>1.79769e+308</upper>
            <effort>-1</effort>
            <velocity>-1</velocity>
          </limit>
          <dynamics>
            <spring_reference>0</spring_reference>
            <spring_stiffness>0</spring_stiffness>
            <damping>0</damping>
          </dynamics>
        </axis>
        <physics>
          <ode>
            <limit>
              <cfm>0</cfm>
              <erp>0.2</erp>
            </limit>
            <suspension>
              <cfm>0</cfm>
              <erp>0.2</erp>
            </suspension>
          </ode>
        </physics>
      </joint>
      <joint name='link_0_JOINT_3' type='revolute'>
        <parent>link_0</parent>
        <child>link_1</child>
        <pose frame=''>0 0 0 0 -0 0</pose>
        <axis>
          <xyz>0 0 1</xyz>
          <use_parent_model_frame>0</use_parent_model_frame>
          <limit>
            <lower>-1.79769e+308</lower>
            <upper>1.79769e+308</upper>
            <effort>-1</effort>
            <velocity>-1</velocity>
          </limit>
          <dynamics>
            <spring_reference>0</spring_reference>
            <spring_stiffness>0</spring_stiffness>
            <damping>0</damping>
          </dynamics>
        </axis>
        <physics>
          <ode>
            <limit>
              <cfm>0</cfm>
              <erp>0.2</erp>
            </limit>
            <suspension>
              <cfm>0</cfm>
              <erp>0.2</erp>
            </suspension>
          </ode>
        </physics>
      </joint>
      <joint name='link_0_JOINT_4' type='revolute'>
        <parent>link_0</parent>
        <child>link_1_clone</child>
        <pose frame=''>0 0 0 0 -0 0</pose>
        <axis>
          <xyz>0 0 1</xyz>
          <use_parent_model_frame>0</use_parent_model_frame>
          <limit>
            <lower>-1.79769e+308</lower>
            <upper>1.79769e+308</upper>
            <effort>-1</effort>
            <velocity>-1</velocity>
          </limit>
          <dynamics>
            <spring_reference>0</spring_reference>
            <spring_stiffness>0</spring_stiffness>
            <damping>0</damping>
          </dynamics>
        </axis>
        <physics>
          <ode>
            <limit>
              <cfm>0</cfm>
              <erp>0.2</erp>
            </limit>
            <suspension>
              <cfm>0</cfm>
              <erp>0.2</erp>
            </suspension>
          </ode>
        </physics>
      </joint>
      <joint name='link_0_JOINT_5' type='revolute'>
        <parent>link_0</parent>
        <child>link_4</child>
        <pose frame=''>0 0 0 0 -0 0</pose>
        <axis>
          <xyz>0 0 1</xyz>
          <use_parent_model_frame>0</use_parent_model_frame>
          <limit>
            <lower>-1.79769e+308</lower>
            <upper>1.79769e+308</upper>
            <effort>-1</effort>
            <velocity>-1</velocity>
          </limit>
          <dynamics>
            <spring_reference>0</spring_reference>
            <spring_stiffness>0</spring_stiffness>
            <damping>0</damping>
          </dynamics>
        </axis>
        <physics>
          <ode>
            <limit>
              <cfm>0</cfm>
              <erp>0.2</erp>
            </limit>
            <suspension>
              <cfm>0</cfm>
              <erp>0.2</erp>
            </suspension>
          </ode>
        </physics>
      </joint>
      <joint name='link_4_JOINT_6' type='revolute'>
        <parent>link_4</parent>
        <child>link_5</child>
        <pose frame=''>0 0 0 0 -0 0</pose>
        <axis>
          <xyz>0 0 1</xyz>
          <use_parent_model_frame>0</use_parent_model_frame>
          <limit>
            <lower>-1.79769e+308</lower>
            <upper>1.79769e+308</upper>
            <effort>-1</effort>
            <velocity>-1</velocity>
          </limit>
          <dynamics>
            <spring_reference>0</spring_reference>
            <spring_stiffness>0</spring_stiffness>
            <damping>0</damping>
          </dynamics>
        </axis>
        <physics>
          <ode>
            <limit>
              <cfm>0</cfm>
              <erp>0.2</erp>
            </limit>
            <suspension>
              <cfm>0</cfm>
              <erp>0.2</erp>
            </suspension>
          </ode>
        </physics>
      </joint>
      <static>0</static>
      <allow_auto_disable>1</allow_auto_disable>
      <pose frame=''>6.32878 7.29764 0.430005 0 -0 0</pose>
    </model>
    <model name='my_ball'>
      <link name='link_0'>
        <pose frame=''>-0 -0 0 0 -0 0</pose>
        <inertial>
          <mass>1</mass>
          <inertia>
            <ixx>0.1</ixx>
            <ixy>0</ixy>
            <ixz>0</ixz>
            <iyy>0.1</iyy>
            <iyz>0</iyz>
            <izz>0.1</izz>
          </inertia>
          <pose frame=''>0 0 0 0 -0 0</pose>
        </inertial>
        <gravity>1</gravity>
        <self_collide>0</self_collide>
        <kinematic>0</kinematic>
        <visual name='visual'>
          <pose frame=''>0 0 0 0 -0 0</pose>
          <geometry>
            <sphere>
              <radius>0.1</radius>
            </sphere>
          </geometry>
          <material>
            <lighting>1</lighting>
            <script>
              <uri>file://media/materials/scripts/gazebo.material</uri>
              <name>Gazebo/Grey</name>
            </script>
            <shader type='pixel'>
              <normal_map>__default__</normal_map>
            </shader>
            <ambient>1 1 1 1</ambient>
            <diffuse>1 1 1 1</diffuse>
            <specular>1 1 1 1</specular>
            <emissive>1 1 1 1</emissive>
          </material>
          <transparency>0</transparency>
          <cast_shadows>1</cast_shadows>
        </visual>
        <collision name='collision'>
          <laser_retro>0</laser_retro>
          <max_contacts>10</max_contacts>
          <pose frame=''>0 0 0 0 -0 0</pose>
          <geometry>
            <sphere>
              <radius>0.1</radius>
            </sphere>
          </geometry>
          <surface>
            <friction>
              <ode>
                <mu>1</mu>
                <mu2>1</mu2>
                <fdir1>0 0 0</fdir1>
                <slip1>0</slip1>
                <slip2>0</slip2>
              </ode>
              <torsional>
                <coefficient>1</coefficient>
                <patch_radius>0</patch_radius>
                <surface_radius>0</surface_radius>
                <use_patch_radius>1</use_patch_radius>
                <ode>
                  <slip>0</slip>
                </ode>
              </torsional>
            </friction>
            <bounce>
              <restitution_coefficient>0</restitution_coefficient>
              <threshold>1e+06</threshold>
            </bounce>
            <contact>
              <collide_without_contact>0</collide_without_contact>
              <collide_without_contact_bitmask>1</collide_without_contact_bitmask>
              <collide_bitmask>1</collide_bitmask>
              <ode>
                <soft_cfm>0</soft_cfm>
                <soft_erp>0.2</soft_erp>
                <kp>1e+13</kp>
                <kd>1</kd>
                <max_vel>0.01</max_vel>
                <min_depth>0</min_depth>
              </ode>
              <bullet>
                <split_impulse>1</split_impulse>
                <split_impulse_penetration_threshold>-0.01</split_impulse_penetration_threshold>
                <soft_cfm>0</soft_cfm>
                <soft_erp>0.2</soft_erp>
                <kp>1e+13</kp>
                <kd>1</kd>
              </bullet>
            </contact>
          </surface>
        </collision>
      </link>
      <static>0</static>
      <allow_auto_disable>1</allow_auto_disable>
      <pose frame=''>3.78034 0.721865 0.5 0 -0 0</pose>
    </model>
  </world>
</sdf>
